<?xml version="1.0" ?>
<sdf version="1.5">
  <world name="default">
    <!-- A global light source -->
    <include>
      <uri>model://sun</uri>
    </include>
    <!-- A ground plane -->
    <include>
      <uri>model://ground_plane</uri>
    </include>    
    <gravity>0 0 0</gravity>

    <model name="uuav">
      <plugin name='set_joint_velocity_plugin' filename='libSetJointVelocityPlugin.so'/>
      <pose frame=''>0 0 2 0 0 0</pose>
      <link name='base_link'>
        <pose frame=''>0 0 0 0 0 0</pose>
        <collision name='base_link_inertia_collision'>
          <pose frame=''>0 0 0 0 -0 0</pose>
          <geometry>
            <box>
              <size>0.24 0.2 0.07</size>
            </box>
          </geometry>
        </collision>
        <visual name='base_link_inertia_visual'>
          <pose frame=''>-0.115 -0.105 -0.04 1.570800 0 1.5708</pose>
          <geometry>
            <mesh>
            <scale>0.001 0.001 0.001</scale>
            <uri>model://uuav/frame.stl</uri>
            </mesh>
          </geometry>
        </visual>
        <gravity>0</gravity>
        <velocity_decay/>
      </link>

      <link name='left_front_rotator'>
        <pose frame=''>0.12 0.1 0.02 0 0 0</pose>
        <collision name='left_front_rotator_inertia_collision'>
          <geometry>
            <cylinder>
              <radius>.025</radius>
              <length>.15</length>
            </cylinder>
          </geometry>
        </collision>
        <visual name='left_front_rotator_inertia_visual'>
          <pose frame=''>-0.02 0.02 -0.085 1.570800 0 0</pose>
          <geometry>
            <mesh>
              <scale>0.001 0.001 0.001</scale>
              <uri>model://uuav/tiltor.STL</uri>
            </mesh>
          </geometry>
        </visual>
      </link>

      <link name='left_back_rotator'>
        <pose frame=''>-0.12 0.1 0.02 0 0 0</pose>
        <collision name='left_back_rotator_inertia_collision'>
          <geometry>
            <cylinder>
              <radius>.025</radius>
              <length>.15</length>
            </cylinder>
          </geometry>
        </collision>
        <visual name='left_back_rotator_inertia_visual'>
          <pose frame=''>-0.02 0.02 -0.085 1.570800 0 0</pose>
          <geometry>
            <mesh>
              <scale>0.001 0.001 0.001</scale>
              <uri>model://uuav/tiltor.STL</uri>
            </mesh>
          </geometry>
        </visual>
      </link>

      <link name='right_back_rotator'>
        <pose frame=''>-0.12 -0.1 0.02 0 0 0</pose>
        <collision name='right_back_rotator_inertia_collision'>
          <geometry>
            <cylinder>
              <radius>.025</radius>
              <length>.15</length>
            </cylinder>
          </geometry>
        </collision>
        <visual name='right_back_rotator_inertia_visual'>
          <pose frame=''>-0.02 0.02 -0.085 1.570800 0 0</pose>
          <geometry>
            <mesh>
              <scale>0.001 0.001 0.001</scale>
              <uri>model://uuav/tiltor.STL</uri>
            </mesh>
          </geometry>
        </visual>
      </link>

      <link name='right_front_rotator'>
        <pose frame=''>0.12 -0.1 0.02 0 0 0</pose>
        <collision name='right_front_rotator_inertia_collision'>
          <geometry>
            <cylinder>
              <radius>.025</radius>
              <length>.15</length>
            </cylinder>
          </geometry>
        </collision>
        <visual name='right_front_rotator_inertia_visual'>
          <pose frame=''>-0.02 0.02 -0.085 1.570800 0 0</pose>
          <geometry>
            <mesh>
              <scale>0.001 0.001 0.001</scale>
              <uri>model://uuav/tiltor.STL</uri>
            </mesh>
          </geometry>
        </visual>
      </link>





      <joint type="revolute" name="right_front_joint">
        <pose>0 0 0 0 0 0</pose>
        <child>right_front_rotator</child>
        <parent>base_link</parent>
        <axis>
          <xyz>-0.10 0.1732 0</xyz>
        </axis>
      </joint>
      <joint type="revolute" name="right_back_joint">
        <pose>0 0 0 0 0 0</pose>
        <child>right_back_rotator</child>
        <parent>base_link</parent>
        <axis>
          <xyz>0.1732 0.1 0</xyz>
        </axis>
      </joint>
      <joint type="revolute" name="left_front_joint">
        <pose>0 0 0 0 0 0</pose>
        <child>left_front_rotator</child>
        <parent>base_link</parent>
        <axis>
          <xyz>0.1732 0.1 0</xyz>
        </axis>
      </joint>  
      <joint type="revolute" name="left_back_joint">
        <pose>0 0 0 0 0 0</pose>
        <child>left_back_rotator</child>
        <parent>base_link</parent>
        <axis>
          <xyz>-0.10 0.1732 0</xyz>
        </axis>
      </joint>




      <link name='rotor_0'>
      <pose frame=''> 0.12 0.1 0.08 0 -0 0</pose>
      <inertial>
        <pose frame=''>0 0 0 0 -0 0</pose>
        <mass>0.005</mass>
        <inertia>
          <ixx>9.75e-07</ixx>
          <ixy>0</ixy>
          <ixz>0</ixz>
          <iyy>0.000273104</iyy>
          <iyz>0</iyz>
          <izz>0.000274004</izz>
        </inertia>
      </inertial>
      <collision name='rotor_0_collision'>
        <pose frame=''>0 0 0 0 -0 0</pose>
        <geometry>
          <cylinder>
            <length>0.005</length>
            <radius>0.084</radius>
          </cylinder>
        </geometry>
        <surface>
          <contact>
            <ode/>
          </contact>
          <friction>
            <ode/>
          </friction>
        </surface>
      </collision>
      <visual name='rotor_0_visual'>
        <pose frame=''>0 0 0 0 -0 0</pose>
        <geometry>
          <mesh>
            <scale>0.67 0.67 0.67</scale>
            <uri>model://rotors_description/meshes/iris_prop_ccw.dae</uri>
          </mesh>
        </geometry>
        <material>
          <script>
            <name>Gazebo/Blue</name>
            <uri>file://media/materials/scripts/gazebo.material</uri>
          </script>
        </material>
      </visual>
      <velocity_decay/>
    </link>
    <joint name='rotor_0_joint' type='revolute'>
      <child>rotor_0</child>
      <parent>left_front_rotator</parent>
      <axis>
        <xyz>0 0 1</xyz>
        <limit>
          <lower>-1e+16</lower>
          <upper>1e+16</upper>
        </limit>
        <dynamics>
          <spring_reference>0</spring_reference>
          <spring_stiffness>0</spring_stiffness>
        </dynamics>
        <use_parent_model_frame>1</use_parent_model_frame>
      </axis>
    </joint>
    <link name='rotor_1'>
      <pose frame=''>-0.12 0.1 0.08 0 -0 0</pose>
      <inertial>
        <pose frame=''>0 0 0 0 -0 0</pose>
        <mass>0.005</mass>
        <inertia>
          <ixx>9.75e-07</ixx>
          <ixy>0</ixy>
          <ixz>0</ixz>
          <iyy>0.000273104</iyy>
          <iyz>0</iyz>
          <izz>0.000274004</izz>
        </inertia>
      </inertial>
      <collision name='rotor_1_collision'>
        <pose frame=''>0 0 0 0 0 0</pose>
        <geometry>
          <cylinder>
            <length>0.05</length>
            <radius>0.084</radius>
          </cylinder>
        </geometry>
        <surface>
          <contact>
            <ode/>
          </contact>
          <friction>
            <ode/>
          </friction>
        </surface>
      </collision>
      <visual name='rotor_1_visual'>
        <pose frame=''>0 0 0 0 0 0</pose>
        <geometry>
          <mesh>
            <scale>0.67 0.67 0.67</scale>
            <uri>model://rotors_description/meshes/iris_prop_ccw.dae</uri>
          </mesh>
        </geometry>
        <material>
          <script>
            <name>Gazebo/DarkGrey</name>
            <uri>file://media/materials/scripts/gazebo.material</uri>
          </script>
        </material>
      </visual>
      <velocity_decay/>
    </link>
    <joint name='rotor_1_joint' type='revolute'>
      <child>rotor_1</child>
      <parent>left_back_rotator</parent>
      <axis>
        <xyz>0 0 1</xyz>
        <limit>
          <lower>-1e+16</lower>
          <upper>1e+16</upper>
        </limit>
        <dynamics>
          <spring_reference>0</spring_reference>
          <spring_stiffness>0</spring_stiffness>
        </dynamics>
        <use_parent_model_frame>1</use_parent_model_frame>
      </axis>
    </joint>
    <link name='rotor_2'>
      <pose frame=''>-0.12 -0.1 0.08 0 -0 0</pose>
      <inertial>
        <pose frame=''>0 0 0 0 -0 0</pose>
        <mass>0.005</mass>
        <inertia>
          <ixx>9.75e-07</ixx>
          <ixy>0</ixy>
          <ixz>0</ixz>
          <iyy>0.000273104</iyy>
          <iyz>0</iyz>
          <izz>0.000274004</izz>
        </inertia>
      </inertial>
      <collision name='rotor_2_collision'>
        <pose frame=''>0 0 0 0 -0 0</pose>
        <geometry>
          <cylinder>
            <length>0.05</length>
            <radius>0.084</radius>
          </cylinder>
        </geometry>
        <surface>
          <contact>
            <ode/>
          </contact>
          <friction>
            <ode/>
          </friction>
        </surface>
      </collision>
      <visual name='rotor_2_visual'>
        <pose frame=''>0 0 0 0 -0 0</pose>
        <geometry>
          <mesh>
            <scale>0.67 0.67 0.67</scale>
            <uri>model://rotors_description/meshes/iris_prop_cw.dae</uri>
          </mesh>
        </geometry>
        <material>
          <script>
            <name>Gazebo/Blue</name>
            <uri>file://media/materials/scripts/gazebo.material</uri>
          </script>
        </material>
      </visual>
      <velocity_decay/>
    </link>
    <joint name='rotor_2_joint' type='revolute'>
      <child>rotor_2</child>
      <parent>right_back_rotator</parent>
      <axis>
        <xyz>0 0 1</xyz>
        <limit>
          <lower>-1e+16</lower>
          <upper>1e+16</upper>
        </limit>
        <dynamics>
          <spring_reference>0</spring_reference>
          <spring_stiffness>0</spring_stiffness>
        </dynamics>
        <use_parent_model_frame>1</use_parent_model_frame>
      </axis>
    </joint>
    <link name='rotor_3'>
      <pose frame=''>0.12 -0.1 0.08 0 -0 0</pose>
      <inertial>
        <pose frame=''>0 0 0 0 -0 0</pose>
        <mass>0.005</mass>
        <inertia>
          <ixx>9.75e-07</ixx>
          <ixy>0</ixy>
          <ixz>0</ixz>
          <iyy>0.000273104</iyy>
          <iyz>0</iyz>
          <izz>0.000274004</izz>
        </inertia>
      </inertial>
      <collision name='rotor_3_collision'>
        <pose frame=''>0 0 0 0 -0 0</pose>
        <geometry>
          <cylinder>
            <length>0.05</length>
            <radius>0.084</radius>
          </cylinder>
        </geometry>
        <surface>
          <contact>
            <ode/>
          </contact>
          <friction>
            <ode/>
          </friction>
        </surface>
      </collision>
      <visual name='rotor_3_visual'>
        <pose frame=''>0 0 0 0 -0 0</pose>
        <geometry>
          <mesh>
            <scale>0.67 0.67 0.67</scale>
            <uri>model://rotors_description/meshes/iris_prop_cw.dae</uri>
          </mesh>
        </geometry>
        <material>
          <script>
            <name>Gazebo/DarkGrey</name>
            <uri>file://media/materials/scripts/gazebo.material</uri>
          </script>
        </material>
      </visual>
      <velocity_decay/>
    </link>
    <joint name='rotor_3_joint' type='revolute'>
      <child>rotor_3</child>
      <parent>right_front_rotator</parent>
      <axis>
        <xyz>0 0 1</xyz>
        <limit>
          <lower>-1e+16</lower>
          <upper>1e+16</upper>
        </limit>
        <dynamics>
          <spring_reference>0</spring_reference>
          <spring_stiffness>0</spring_stiffness>
        </dynamics>
        <use_parent_model_frame>1</use_parent_model_frame>
      </axis>
    </joint>
    </model>
  </world>
</sdf>
